{
 "cells": [
  {
   "cell_type": "code",
   "execution_count": 144,
   "metadata": {},
   "outputs": [],
   "source": [
    "import numpy as np\n",
    "from sklearn import metrics\n",
    "from keras import backend as K\n",
    "from keras.models import Sequential\n",
    "from keras.layers.core import Dense, Dropout, Activation, Flatten\n",
    "from keras.layers.convolutional import Convolution2D, MaxPooling2D\n",
    "from keras.preprocessing.image import ImageDataGenerator\n",
    "from sklearn.metrics import classification_report, confusion_matrix\n",
    "import numpy as np\n",
    "import tensorflow as tf\n",
    "from tensorflow import keras\n",
    "from tensorflow.keras.preprocessing.text import Tokenizer\n",
    "from tensorflow.keras.layers import Embedding, LSTM, Dense, Bidirectional\n",
    "from tensorflow import keras\n",
    "from tensorflow.keras import layers\n",
    "from keras.applications.mobilenet_v2 import decode_predictions\n",
    "\n",
    "import matplotlib.pyplot as plt\n"
   ]
  },
  {
   "cell_type": "code",
   "execution_count": 145,
   "metadata": {},
   "outputs": [
    {
     "name": "stdout",
     "output_type": "stream",
     "text": [
      "Deleted 0 images\n"
     ]
    }
   ],
   "source": [
    "import os\n",
    "num_skipped = 0\n",
    "for folder_name in (\"Cat\", \"Dog\"):\n",
    "\n",
    "    folder_path = os.path.join(\"C://Users//mhalama//Desktop//DATA_SET//PetImages\", folder_name)\n",
    "    for fname in os.listdir(folder_path):\n",
    "        fpath = os.path.join(folder_path, fname)\n",
    "        try:\n",
    "            fobj = open(fpath, \"rb\")\n",
    "            is_jfif = tf.compat.as_bytes(\"JFIF\") in fobj.peek(10)\n",
    "        finally:\n",
    "            fobj.close()\n",
    "\n",
    "        if not is_jfif:\n",
    "            num_skipped += 1\n",
    "            # Delete corrupted image\n",
    "            os.remove(fpath)\n",
    "\n",
    "print(\"Deleted %d images\" % num_skipped)"
   ]
  },
  {
   "cell_type": "code",
   "execution_count": 146,
   "metadata": {},
   "outputs": [
    {
     "name": "stdout",
     "output_type": "stream",
     "text": [
      "Found 23422 files belonging to 2 classes.\n",
      "Using 5856 files for training.\n",
      "Using 17566 files for validation.\n"
     ]
    }
   ],
   "source": [
    "#generator bazy danych obrazków kotków i piesków\n",
    "\n",
    "\n",
    "image_size = (299, 299)\n",
    "batch_size = 32\n",
    "\n",
    "train_ds, val_ds= tf.keras.preprocessing.image_dataset_from_directory(\n",
    "    \"C://Users//mhalama//Desktop//DATA_SET//PetImages\",\n",
    "    validation_split=0.75,\n",
    "    subset=\"both\",\n",
    "    seed=1337,\n",
    "    image_size=image_size,\n",
    "    batch_size=batch_size,\n",
    ")"
   ]
  },
  {
   "cell_type": "code",
   "execution_count": 148,
   "metadata": {},
   "outputs": [
    {
     "name": "stdout",
     "output_type": "stream",
     "text": [
      "Epoch 1/10\n",
      "169/183 [==========================>...] - ETA: 42s - loss: 7.7235 - accuracy: 0.4911"
     ]
    }
   ],
   "source": [
    "base_model = keras.applications.Xception(\n",
    "    weights=\"imagenet\",\n",
    "    input_shape=(299, 299, 3),\n",
    "    include_top=False\n",
    ")\n",
    "\n",
    "#po kolei warstwy:\n",
    "# for i,layer in enumerate(base_model.layers):\n",
    "#     print(i,layer.name)\n",
    "#budowana nowego modelu i zamrazanie starego \n",
    "base_model.trainable = False\n",
    "inputs = keras.Input(shape=(299, 299, 3))\n",
    "x = base_model(inputs, training=False)\n",
    "x = keras.layers.GlobalAveragePooling2D()(x)\n",
    "outputs = keras.layers.Dense(1)(x)\n",
    "tf.keras.applications.xception.preprocess_input(x, data_format=None)\n",
    "model = keras.Model(inputs, outputs)\n",
    "\n",
    "\n",
    "model.compile(loss='BinaryCrossentropy',\n",
    "              optimizer='Adam',\n",
    "              metrics=['accuracy'])\n",
    "\n",
    "\n",
    "history = model.fit(train_ds, epochs=10, validation_split=0.3, validation_data =val_ds)\n",
    "\n",
    "# y_pred = model.predict(x_test)\n",
    "\n",
    "# print(confusion_matrix(x_test, y_pred))"
   ]
  },
  {
   "cell_type": "code",
   "execution_count": null,
   "metadata": {},
   "outputs": [
    {
     "ename": "NameError",
     "evalue": "name 'history' is not defined",
     "output_type": "error",
     "traceback": [
      "\u001b[1;31m---------------------------------------------------------------------------\u001b[0m",
      "\u001b[1;31mNameError\u001b[0m                                 Traceback (most recent call last)",
      "Cell \u001b[1;32mIn [142], line 4\u001b[0m\n\u001b[0;32m      1\u001b[0m \u001b[39m#wykresy funkcji straty i\u001b[39;00m\n\u001b[1;32m----> 4\u001b[0m plt\u001b[39m.\u001b[39mplot(history\u001b[39m.\u001b[39mhistory[\u001b[39m'\u001b[39m\u001b[39mbinary_accuracy\u001b[39m\u001b[39m'\u001b[39m])\n\u001b[0;32m      5\u001b[0m plt\u001b[39m.\u001b[39mplot(history\u001b[39m.\u001b[39mhistory[\u001b[39m'\u001b[39m\u001b[39mval_binary_accuracy\u001b[39m\u001b[39m'\u001b[39m])\n\u001b[0;32m      6\u001b[0m plt\u001b[39m.\u001b[39mtitle(\u001b[39m'\u001b[39m\u001b[39mmodel accuracy\u001b[39m\u001b[39m'\u001b[39m)\n",
      "\u001b[1;31mNameError\u001b[0m: name 'history' is not defined"
     ]
    }
   ],
   "source": [
    "#wykresy funkcji straty i\n",
    "\n",
    "\n",
    "plt.plot(history.history['binary_accuracy'])\n",
    "plt.plot(history.history['val_binary_accuracy'])\n",
    "plt.title('model accuracy')\n",
    "plt.ylabel('accuracy')\n",
    "plt.xlabel('epoch')\n",
    "plt.legend(['train', 'validation'], loc='upper left')\n",
    "plt.show()\n",
    "\n",
    "\n",
    "plt.plot(history.history['loss'])\n",
    "plt.plot(history.history['val_loss'])\n",
    "plt.title('model loss')\n",
    "plt.ylabel('loss')\n",
    "plt.xlabel('epoch')\n",
    "plt.legend(['train', 'validation'], loc='upper left')\n",
    "plt.show()"
   ]
  },
  {
   "cell_type": "code",
   "execution_count": null,
   "metadata": {},
   "outputs": [
    {
     "ename": "InvalidArgumentError",
     "evalue": "Graph execution error:\n\nDetected at node 'IteratorGetNext' defined at (most recent call last):\n    File \"c:\\Program Files\\Python310\\lib\\runpy.py\", line 196, in _run_module_as_main\n      return _run_code(code, main_globals, None,\n    File \"c:\\Program Files\\Python310\\lib\\runpy.py\", line 86, in _run_code\n      exec(code, run_globals)\n    File \"C:\\Users\\mhalama\\AppData\\Roaming\\Python\\Python310\\site-packages\\ipykernel_launcher.py\", line 17, in <module>\n      app.launch_new_instance()\n    File \"C:\\Users\\mhalama\\AppData\\Roaming\\Python\\Python310\\site-packages\\traitlets\\config\\application.py\", line 978, in launch_instance\n      app.start()\n    File \"C:\\Users\\mhalama\\AppData\\Roaming\\Python\\Python310\\site-packages\\ipykernel\\kernelapp.py\", line 712, in start\n      self.io_loop.start()\n    File \"C:\\Users\\mhalama\\AppData\\Roaming\\Python\\Python310\\site-packages\\tornado\\platform\\asyncio.py\", line 215, in start\n      self.asyncio_loop.run_forever()\n    File \"c:\\Program Files\\Python310\\lib\\asyncio\\base_events.py\", line 600, in run_forever\n      self._run_once()\n    File \"c:\\Program Files\\Python310\\lib\\asyncio\\base_events.py\", line 1896, in _run_once\n      handle._run()\n    File \"c:\\Program Files\\Python310\\lib\\asyncio\\events.py\", line 80, in _run\n      self._context.run(self._callback, *self._args)\n    File \"C:\\Users\\mhalama\\AppData\\Roaming\\Python\\Python310\\site-packages\\ipykernel\\kernelbase.py\", line 510, in dispatch_queue\n      await self.process_one()\n    File \"C:\\Users\\mhalama\\AppData\\Roaming\\Python\\Python310\\site-packages\\ipykernel\\kernelbase.py\", line 499, in process_one\n      await dispatch(*args)\n    File \"C:\\Users\\mhalama\\AppData\\Roaming\\Python\\Python310\\site-packages\\ipykernel\\kernelbase.py\", line 406, in dispatch_shell\n      await result\n    File \"C:\\Users\\mhalama\\AppData\\Roaming\\Python\\Python310\\site-packages\\ipykernel\\kernelbase.py\", line 730, in execute_request\n      reply_content = await reply_content\n    File \"C:\\Users\\mhalama\\AppData\\Roaming\\Python\\Python310\\site-packages\\ipykernel\\ipkernel.py\", line 383, in do_execute\n      res = shell.run_cell(\n    File \"C:\\Users\\mhalama\\AppData\\Roaming\\Python\\Python310\\site-packages\\ipykernel\\zmqshell.py\", line 528, in run_cell\n      return super().run_cell(*args, **kwargs)\n    File \"C:\\Users\\mhalama\\AppData\\Roaming\\Python\\Python310\\site-packages\\IPython\\core\\interactiveshell.py\", line 2885, in run_cell\n      result = self._run_cell(\n    File \"C:\\Users\\mhalama\\AppData\\Roaming\\Python\\Python310\\site-packages\\IPython\\core\\interactiveshell.py\", line 2940, in _run_cell\n      return runner(coro)\n    File \"C:\\Users\\mhalama\\AppData\\Roaming\\Python\\Python310\\site-packages\\IPython\\core\\async_helpers.py\", line 129, in _pseudo_sync_runner\n      coro.send(None)\n    File \"C:\\Users\\mhalama\\AppData\\Roaming\\Python\\Python310\\site-packages\\IPython\\core\\interactiveshell.py\", line 3139, in run_cell_async\n      has_raised = await self.run_ast_nodes(code_ast.body, cell_name,\n    File \"C:\\Users\\mhalama\\AppData\\Roaming\\Python\\Python310\\site-packages\\IPython\\core\\interactiveshell.py\", line 3318, in run_ast_nodes\n      if await self.run_code(code, result, async_=asy):\n    File \"C:\\Users\\mhalama\\AppData\\Roaming\\Python\\Python310\\site-packages\\IPython\\core\\interactiveshell.py\", line 3378, in run_code\n      exec(code_obj, self.user_global_ns, self.user_ns)\n    File \"C:\\Users\\mhalama\\AppData\\Local\\Temp\\ipykernel_14852\\1713991201.py\", line 1, in <module>\n      y_pred = np.argmax(model.predict(y_pred), axis=1)\n    File \"C:\\Users\\mhalama\\AppData\\Roaming\\Python\\Python310\\site-packages\\keras\\utils\\traceback_utils.py\", line 65, in error_handler\n      return fn(*args, **kwargs)\n    File \"C:\\Users\\mhalama\\AppData\\Roaming\\Python\\Python310\\site-packages\\keras\\engine\\training.py\", line 2253, in predict\n      tmp_batch_outputs = self.predict_function(iterator)\n    File \"C:\\Users\\mhalama\\AppData\\Roaming\\Python\\Python310\\site-packages\\keras\\engine\\training.py\", line 2041, in predict_function\n      return step_function(self, iterator)\n    File \"C:\\Users\\mhalama\\AppData\\Roaming\\Python\\Python310\\site-packages\\keras\\engine\\training.py\", line 2026, in step_function\n      data = next(iterator)\nNode: 'IteratorGetNext'\nCannot batch tensors with different shapes in component 0. First element had shape [316,300,3] and element 6 had shape [375,500,3].\n\t [[{{node IteratorGetNext}}]] [Op:__inference_predict_function_190445]",
     "output_type": "error",
     "traceback": [
      "\u001b[1;31m---------------------------------------------------------------------------\u001b[0m",
      "\u001b[1;31mInvalidArgumentError\u001b[0m                      Traceback (most recent call last)",
      "Cell \u001b[1;32mIn [43], line 1\u001b[0m\n\u001b[1;32m----> 1\u001b[0m y_pred \u001b[39m=\u001b[39m np\u001b[39m.\u001b[39margmax(model\u001b[39m.\u001b[39mpredict(y_pred), axis\u001b[39m=\u001b[39m\u001b[39m1\u001b[39m)\n\u001b[0;32m      2\u001b[0m y_true \u001b[39m=\u001b[39m model\u001b[39m.\u001b[39mpredicted(val_ds)\n\u001b[0;32m      4\u001b[0m confusion_matrix \u001b[39m=\u001b[39m metrics\u001b[39m.\u001b[39mconfusion_matrix(y_pred, y_true)\n",
      "File \u001b[1;32m~\\AppData\\Roaming\\Python\\Python310\\site-packages\\keras\\utils\\traceback_utils.py:70\u001b[0m, in \u001b[0;36mfilter_traceback.<locals>.error_handler\u001b[1;34m(*args, **kwargs)\u001b[0m\n\u001b[0;32m     67\u001b[0m     filtered_tb \u001b[39m=\u001b[39m _process_traceback_frames(e\u001b[39m.\u001b[39m__traceback__)\n\u001b[0;32m     68\u001b[0m     \u001b[39m# To get the full stack trace, call:\u001b[39;00m\n\u001b[0;32m     69\u001b[0m     \u001b[39m# `tf.debugging.disable_traceback_filtering()`\u001b[39;00m\n\u001b[1;32m---> 70\u001b[0m     \u001b[39mraise\u001b[39;00m e\u001b[39m.\u001b[39mwith_traceback(filtered_tb) \u001b[39mfrom\u001b[39;00m \u001b[39mNone\u001b[39m\n\u001b[0;32m     71\u001b[0m \u001b[39mfinally\u001b[39;00m:\n\u001b[0;32m     72\u001b[0m     \u001b[39mdel\u001b[39;00m filtered_tb\n",
      "File \u001b[1;32m~\\AppData\\Roaming\\Python\\Python310\\site-packages\\tensorflow\\python\\eager\\execute.py:54\u001b[0m, in \u001b[0;36mquick_execute\u001b[1;34m(op_name, num_outputs, inputs, attrs, ctx, name)\u001b[0m\n\u001b[0;32m     52\u001b[0m \u001b[39mtry\u001b[39;00m:\n\u001b[0;32m     53\u001b[0m   ctx\u001b[39m.\u001b[39mensure_initialized()\n\u001b[1;32m---> 54\u001b[0m   tensors \u001b[39m=\u001b[39m pywrap_tfe\u001b[39m.\u001b[39mTFE_Py_Execute(ctx\u001b[39m.\u001b[39m_handle, device_name, op_name,\n\u001b[0;32m     55\u001b[0m                                       inputs, attrs, num_outputs)\n\u001b[0;32m     56\u001b[0m \u001b[39mexcept\u001b[39;00m core\u001b[39m.\u001b[39m_NotOkStatusException \u001b[39mas\u001b[39;00m e:\n\u001b[0;32m     57\u001b[0m   \u001b[39mif\u001b[39;00m name \u001b[39mis\u001b[39;00m \u001b[39mnot\u001b[39;00m \u001b[39mNone\u001b[39;00m:\n",
      "\u001b[1;31mInvalidArgumentError\u001b[0m: Graph execution error:\n\nDetected at node 'IteratorGetNext' defined at (most recent call last):\n    File \"c:\\Program Files\\Python310\\lib\\runpy.py\", line 196, in _run_module_as_main\n      return _run_code(code, main_globals, None,\n    File \"c:\\Program Files\\Python310\\lib\\runpy.py\", line 86, in _run_code\n      exec(code, run_globals)\n    File \"C:\\Users\\mhalama\\AppData\\Roaming\\Python\\Python310\\site-packages\\ipykernel_launcher.py\", line 17, in <module>\n      app.launch_new_instance()\n    File \"C:\\Users\\mhalama\\AppData\\Roaming\\Python\\Python310\\site-packages\\traitlets\\config\\application.py\", line 978, in launch_instance\n      app.start()\n    File \"C:\\Users\\mhalama\\AppData\\Roaming\\Python\\Python310\\site-packages\\ipykernel\\kernelapp.py\", line 712, in start\n      self.io_loop.start()\n    File \"C:\\Users\\mhalama\\AppData\\Roaming\\Python\\Python310\\site-packages\\tornado\\platform\\asyncio.py\", line 215, in start\n      self.asyncio_loop.run_forever()\n    File \"c:\\Program Files\\Python310\\lib\\asyncio\\base_events.py\", line 600, in run_forever\n      self._run_once()\n    File \"c:\\Program Files\\Python310\\lib\\asyncio\\base_events.py\", line 1896, in _run_once\n      handle._run()\n    File \"c:\\Program Files\\Python310\\lib\\asyncio\\events.py\", line 80, in _run\n      self._context.run(self._callback, *self._args)\n    File \"C:\\Users\\mhalama\\AppData\\Roaming\\Python\\Python310\\site-packages\\ipykernel\\kernelbase.py\", line 510, in dispatch_queue\n      await self.process_one()\n    File \"C:\\Users\\mhalama\\AppData\\Roaming\\Python\\Python310\\site-packages\\ipykernel\\kernelbase.py\", line 499, in process_one\n      await dispatch(*args)\n    File \"C:\\Users\\mhalama\\AppData\\Roaming\\Python\\Python310\\site-packages\\ipykernel\\kernelbase.py\", line 406, in dispatch_shell\n      await result\n    File \"C:\\Users\\mhalama\\AppData\\Roaming\\Python\\Python310\\site-packages\\ipykernel\\kernelbase.py\", line 730, in execute_request\n      reply_content = await reply_content\n    File \"C:\\Users\\mhalama\\AppData\\Roaming\\Python\\Python310\\site-packages\\ipykernel\\ipkernel.py\", line 383, in do_execute\n      res = shell.run_cell(\n    File \"C:\\Users\\mhalama\\AppData\\Roaming\\Python\\Python310\\site-packages\\ipykernel\\zmqshell.py\", line 528, in run_cell\n      return super().run_cell(*args, **kwargs)\n    File \"C:\\Users\\mhalama\\AppData\\Roaming\\Python\\Python310\\site-packages\\IPython\\core\\interactiveshell.py\", line 2885, in run_cell\n      result = self._run_cell(\n    File \"C:\\Users\\mhalama\\AppData\\Roaming\\Python\\Python310\\site-packages\\IPython\\core\\interactiveshell.py\", line 2940, in _run_cell\n      return runner(coro)\n    File \"C:\\Users\\mhalama\\AppData\\Roaming\\Python\\Python310\\site-packages\\IPython\\core\\async_helpers.py\", line 129, in _pseudo_sync_runner\n      coro.send(None)\n    File \"C:\\Users\\mhalama\\AppData\\Roaming\\Python\\Python310\\site-packages\\IPython\\core\\interactiveshell.py\", line 3139, in run_cell_async\n      has_raised = await self.run_ast_nodes(code_ast.body, cell_name,\n    File \"C:\\Users\\mhalama\\AppData\\Roaming\\Python\\Python310\\site-packages\\IPython\\core\\interactiveshell.py\", line 3318, in run_ast_nodes\n      if await self.run_code(code, result, async_=asy):\n    File \"C:\\Users\\mhalama\\AppData\\Roaming\\Python\\Python310\\site-packages\\IPython\\core\\interactiveshell.py\", line 3378, in run_code\n      exec(code_obj, self.user_global_ns, self.user_ns)\n    File \"C:\\Users\\mhalama\\AppData\\Local\\Temp\\ipykernel_14852\\1713991201.py\", line 1, in <module>\n      y_pred = np.argmax(model.predict(y_pred), axis=1)\n    File \"C:\\Users\\mhalama\\AppData\\Roaming\\Python\\Python310\\site-packages\\keras\\utils\\traceback_utils.py\", line 65, in error_handler\n      return fn(*args, **kwargs)\n    File \"C:\\Users\\mhalama\\AppData\\Roaming\\Python\\Python310\\site-packages\\keras\\engine\\training.py\", line 2253, in predict\n      tmp_batch_outputs = self.predict_function(iterator)\n    File \"C:\\Users\\mhalama\\AppData\\Roaming\\Python\\Python310\\site-packages\\keras\\engine\\training.py\", line 2041, in predict_function\n      return step_function(self, iterator)\n    File \"C:\\Users\\mhalama\\AppData\\Roaming\\Python\\Python310\\site-packages\\keras\\engine\\training.py\", line 2026, in step_function\n      data = next(iterator)\nNode: 'IteratorGetNext'\nCannot batch tensors with different shapes in component 0. First element had shape [316,300,3] and element 6 had shape [375,500,3].\n\t [[{{node IteratorGetNext}}]] [Op:__inference_predict_function_190445]"
     ]
    }
   ],
   "source": [
    "y_pred = np.argmax(model.predict(train_ds), axis=1)\n",
    "y_true = model.predicted(val_ds)\n",
    "\n",
    "confusion_matrix = metrics.confusion_matrix(y_pred, y_true)\n",
    "cm_display = metrics.ConfusionMatrixDisplay(\n",
    "    confusion_matrix = confusion_matrix, display_labels = [False, True])\n",
    "\n",
    "\n",
    "cm_display.plot()\n",
    "plt.show()  "
   ]
  }
 ],
 "metadata": {
  "kernelspec": {
   "display_name": "Python 3",
   "language": "python",
   "name": "python3"
  },
  "language_info": {
   "codemirror_mode": {
    "name": "ipython",
    "version": 3
   },
   "file_extension": ".py",
   "mimetype": "text/x-python",
   "name": "python",
   "nbconvert_exporter": "python",
   "pygments_lexer": "ipython3",
   "version": "3.10.7"
  },
  "orig_nbformat": 4,
  "vscode": {
   "interpreter": {
    "hash": "26de051ba29f2982a8de78e945f0abaf191376122a1563185a90213a26c5da77"
   }
  }
 },
 "nbformat": 4,
 "nbformat_minor": 2
}
